Traceback (most recent call last):
  File "/home/jiviteshdg/.local/lib/python3.9/site-packages/luma/core/interface/serial.py", line 93, in command
    self._bus.write_i2c_block_data(self._addr, self._cmd_mode,
  File "/home/jiviteshdg/.local/lib/python3.9/site-packages/smbus2/smbus2.py", line 643, in write_i2c_block_data
    ioctl(self.fd, I2C_SMBUS, msg)
OSError: [Errno 121] Remote I/O error

During handling of the above exception, another exception occurred:

Traceback (most recent call last):
  File "/home/jiviteshdg/Documents/oled.py", line 12, in <module>
    device = ssd1306(serial, width=128, height=32)
  File "/home/jiviteshdg/.local/lib/python3.9/site-packages/luma/oled/device/__init__.py", line 262, in __init__
    self.command(
  File "/home/jiviteshdg/.local/lib/python3.9/site-packages/luma/core/device.py", line 48, in command
    self._serial_interface.command(*cmd)
  File "/home/jiviteshdg/.local/lib/python3.9/site-packages/luma/core/interface/serial.py", line 98, in command
    raise luma.core.error.DeviceNotFoundError(
luma.core.error.DeviceNotFoundError: I2C device not found on address: 0x3C
